Workbook

Sheet Deckblatt
A1: Fußbodenheizung – Auslegung nach DIN EN 1264
A2: Eingaben · Verarbeitung · Ergebnisse
A3: ="Projekt-Nr.: "&'Grundeinstellungen'!$C$2&" Projekt: "&'Grundeinstellungen'!$C$3&" Bearbeiter: "&'Grundeinstellungen'!$M$2
A5: EINGABEN | E5: BERECHNUNG | I5: ERGEBNISSE
A6: Globale Vorgaben | D6: → | E6: Heizleistung nach oben (EN 1264) | H6: → | I6: Je Raum
A7: • Vorlauf- und Rücklauftemperatur | E7: q = B · aB · aTmT · aümü · aDmD · ΔθH | I7: • Spezifische Heizleistung
A8: • Rohrsystem und Stoffwerte | E8: ΔθH = (θV − θR) / ln[(θV − θi) / (θR − θi)] | I8: • Oberflächentemperatur
A9: • Wärmeübergang und Estrichaufbau | E9: mT = 1 − Abstand / 0,075 | I9: • Deckungsgrad (Ampelbewertung)
A10: • Dämmung nach unten | E10: • Faktoren je R-Wert (Konstanten-Tabelle) | I10: • Rohrlänge je Heizkreis (Ampel)
A11: • Grenzwerte (Länge, Druck, Strömung) | E11: Oberflächentemperatur | I11: • Massenstrom und Volumenstrom
A12: Je Raum | E12: θF = θi + q / α | I12: • Strömungsgeschwindigkeit
A13: • Raumfläche und aktivierbare Fläche | E13: Hydraulik / Druckverlust | I13: • Druckverlust je Heizkreis (Ampel)
A14: • Heizlast und Raumtemperatur | E14: • Maßgebliche Leistung → Massenstrom | I14: Je Heizkreisverteiler
A15: • Bodenbelag-Widerstand, Verlegeabstand | E15: Δp = λ · (L / di) · (ρ / 2) · v² | I15: • Leistung und Volumenstrom
A16: • Anzahl Heizkreise, Zuleitung, Zone | E16: • Strömung: Reynolds-Zahl, Rohrreibung | I16: • Maximaler Druckverlust
A17: • Heizkreisverteiler | E17: • Rohrlängen je Heizkreis | I17: Gesamt
A18: EN-1264-Faktoren | E18: Prüfungen (Ampelbewertung) | I18: • Kontrolle und Warnübersicht
A19: • B, a_B, a_T, a_ü, a_D (Konstanten) | E19: • Deckung, Temperatur, Druckverlust
A22: Formelzeichen: θV / θR Vorlauf- / Rücklauftemperatur · θi Raumtemperatur · θF Oberflächentemperatur · B Systemkoeffizient · a_B / a_T Bodenbelag- / Teilungsfaktor · a_ü / a_D Überdeckungs- / Durchmesserfaktor · α Wärmeübergangskoeffizient · λ Rohrreibungszahl · ρ Dichte · v Strömungsgeschwindigkeit
A23: Überschlägige Auslegung – Vereinfachungen und Annahmen siehe Blatt „Methodik“.

Sheet Grundeinstellungen
A1: Globale Grundeinstellungen – Fußbodenheizung (DIN EN 1264)
A2: Projekt-Nr. | L2: Bearbeiter:
A3: Projektname
A5: Heizmedium / Temperaturen | H5: Wärmeübergang / Fußbodenaufbau
A6: Vorlauftemperatur θV | C6: 35 | D6: °C | E6: Auslegungs-Vorlauf | H6: Wärmeübergang Oberfläche α | J6: 10.8 | K6: W/m²K | L6: Boden → Raum (EN 1264)
A7: Rücklauftemperatur θR | C7: 28 | D7: °C | E7: Auslegungs-Rücklauf | H7: Estrichüberdeckung über Rohr sü | J7: 0.045 | K7: m | L7: Estrich über den Rohren
A8: Spreizung θV − θR | C8: =C6-C7 | D8: K | E8: berechnet | H8: Wärmeleitfähigkeit Estrich λE | J8: 1.2 | K8: W/mK | L8: Zementestrich typ. 1,2
A10: Grenzwerte | H10: Wärmeabgabe nach unten (Dämmung, global)
A11: Maximale zulässige Kreislänge | C11: 120 | D11: m | E11: Obergrenze je Heizkreis | H11: Wärmedurchlasswiderstand Ru | J11: 2 | K11: m²K/W | L11: Dämmung unter den Rohren
A12: Maximaler Druckverlust je Kreis | C12: 15000 | D12: Pa | E12: Warnschwelle | H12: Temperatur unter der Decke θu | J12: 10 | K12: °C | L12: Raum/Erdreich unter FBH
H13: Wärmestrom nach unten qu | J13: =((C6+C7)/2-J12)/J11 | K13: W/m² | L13: Mittel θm = (θV+θR)/2
A14: Stoffwerte Heizmedium (Wasser ~30 °C)
A15: Dichte ρ | C15: 995.7 | D15: kg/m³ | E15: Dichte des Mediums | H15: Rohrsystem-Auswahl (Werte aus Konstanten)
A16: spezifische Wärmekapazität cp | C16: 4180 | D16: J/(kg·K) | E16: spez. Wärmekapazität | H16: Gewähltes Rohrsystem | J16: PE-Xa 17x2 | L16: Dropdown
A17: kinematische Viskosität ν | C17: 8.01e-07 | D17: m²/s | E17: für die Reynolds-Zahl | H17: → Außendurchmesser da | J17: =VLOOKUP($J$16,'Konstanten'!$A$18:$E$25,2,FALSE) | K17: mm | L17: aus Rohrbibliothek
H18: → Wandstärke s | J18: =VLOOKUP($J$16,'Konstanten'!$A$18:$E$25,3,FALSE) | K18: mm | L18: aus Rohrbibliothek
A19: Strömungsgrenzwerte | H19: → Innendurchmesser di | J19: =VLOOKUP($J$16,'Konstanten'!$A$18:$E$25,4,FALSE) | K19: mm | L19: di = da − 2·s
A20: Minimale Geschwindigkeit vmin | C20: 0.1 | D20: m/s | E20: untere empfohlene Grenze | H20: → Rauheit k | J20: =VLOOKUP($J$16,'Konstanten'!$A$18:$E$25,5,FALSE) | K20: mm | L20: aus Rohrbibliothek
A21: Maximale Geschwindigkeit vmax | C21: 0.5 | D21: m/s | E21: obere empfohlene Grenze | H21: → Innendurchmesser di | J21: =J19/1000 | K21: m | L21: für die Berechnung
A22: Max. Volumenstrom je Kreis V̇max | C22: 150 | D22: l/h | E22: Warnschwelle je Heizkreis | H22: → Innenquerschnitt Ai | J22: =PI()/4*J21^2 | K22: m² | L22: für die Berechnung
A23: Druckverlust-Zuschläge | H23: Gilt für Bauart A nach DIN EN 1264 (Heizrohre im Estrich).
A24: Zuschlag Einzelwiderstände | C24: 0.05 | D24: - | E24: Formstücke (5 %)
A25: Aufschlag Verteiler je Kreis | C25: 500 | D25: Pa | E25: fester Wert je Verteiler

Sheet Auslegung
A1: Fußbodenheizung – Auslegung (DIN EN 1264)
A2: ="Projekt-Nr. "&'Grundeinstellungen'!$C$2&" Projekt "&'Grundeinstellungen'!$C$3 | AB2: ="Bearbeiter "&'Grundeinstellungen'!$M$2
A4: Heizkreis- verteiler | B4: Raum-Nr. | C4: Raum- bezeichnung | D4: Raum-fläche | E4: Raum- temperatur | F4: Heizlast | G4: spez. Heizlast | H4: aktivier- bare Fläche | I4: R-Wert Bodenbelag | J4: Verlege–abstand | K4: Anz. HK | L4: Zuleitungs- länge | M4: Zone | N4: log. Übertemperatur | O4: Bodenbelag-Faktor | P4: Teilungs- faktor | Q4: spez. Heiz- leistung | R4: Ober- flächen- temperatur | S4: max. Oberflächentemp. | T4: Leistung FBH | U4: Über-/Unter- deckung | V4: Deckung | W4: Verlust nach unten | X4: maßgebl. Leistung | Y4: Rohrlänge Fläche | Z4: Rohrlänge Zuleitung | AA4: Rohrlänge gesamt | AB4: Rohrlänge je Kreis | AC4: Massenstrom je Kreis | AD4: Volumen-strom je Kreis | AE4: Geschwin-digkeit | AF4: Reynolds-Zahl | AG4: Strömungsbereich | AH4: Rohrreibungszahl | AI4: Δp Reibung | AJ4: spez. Druckverlust | AK4: Druck- verlust
A5: HKV | D5: AR | E5: θi | F5: Q | G5: qHL | H5: AF | I5: Rλ,B | J5: VA | K5: n | L5: Lzu | N5: ΔθH | O5: aB | P5: aT | Q5: q | R5: θF | S5: θF,max | T5: Qo | U5: ΔQ | W5: Qu | X5: Qm | Y5: LF | Z5: LZ | AA5: Lges | AB5: LK | AC5: ṁ | AD5: V̇ | AE5: v | AF5: Re | AH5: λ | AI5: ΔpR | AJ5: R | AK5: Δp
D6: [m²] | E6: [°C] | F6: [W] | G6: [W/m²] | H6: [m²] | I6: [m²·K/W] | J6: [mm] | K6: [-] | L6: [m] | N6: [K] | O6: [-] | P6: [-] | Q6: [W/m²] | R6: [°C] | S6: [°C] | T6: [W] | U6: [W] | V6: [%] | W6: [W] | X6: [W] | Y6: [m] | Z6: [m] | AA6: [m] | AB6: [m] | AC6: [kg/h] | AD6: [l/h] | AE6: [m/s] | AF6: [-] | AG6: [-] | AH6: [-] | AI6: [Pa] | AJ6: [Pa/m] | AK6: [Pa]
A7: HKV EG | B7: 001 | C7: Foyer/Empfang | D7: 40 | E7: 20 | F7: 1800 | G7: =IF($B7="","",IFERROR($F7/$D7,"")) | H7: 36 | I7: 0 | J7: 100 | K7: 3 | L7: 6 | M7: RZ | N7: =IF($B7="","",IFERROR(('Grundeinstellungen'!$C$6-'Grundeinstellungen'!$C$7)/LN(('Grundeinstellungen'!$C$6-$E7)/('Grundeinstellungen'!$C$7-$E7)),"")) | O7: =IF($B7="","",IFERROR(IFERROR(INDEX('Konstanten'!$B$6:$B$10,MATCH($I7,'Konstanten'!$A$6:$A$10,1))+($I7-INDEX('Konstanten'!$A$6:$A$10,MATCH($I7,'Konstanten'!$A$6:$A$10,1)))/(INDEX('Konstanten'!$A$6:$A$10,MATCH($I7,'Konstanten'!$A$6:$A$10,1)+1)-INDEX('Konstanten'!$A$6:$A$10,MATCH($I7,'Konstanten'!$A$6:$A$10,1)))*(INDEX('Konstanten'!$B$6:$B$10,MATCH($I7,'Konstanten'!$A$6:$A$10,1)+1)-INDEX('Konstanten'!$B$6:$B$10,MATCH($I7,'Konstanten'!$A$6:$A$10,1))),INDEX('Konstanten'!$B$6:$B$10,MATCH($I7,'Konstanten'!$A$6:$A$10,1))),"")) | P7: =IF($B7="","",IFERROR(IFERROR(INDEX('Konstanten'!$C$6:$C$10,MATCH($I7,'Konstanten'!$A$6:$A$10,1))+($I7-INDEX('Konstanten'!$A$6:$A$10,MATCH($I7,'Konstanten'!$A$6:$A$10,1)))/(INDEX('Konstanten'!$A$6:$A$10,MATCH($I7,'Konstanten'!$A$6:$A$10,1)+1)-INDEX('Konstanten'!$A$6:$A$10,MATCH($I7,'Konstanten'!$A$6:$A$10,1)))*(INDEX('Konstanten'!$C$6:$C$10,MATCH($I7,'Konstanten'!$A$6:$A$10,1)+1)-INDEX('Konstanten'!$C$6:$C$10,MATCH($I7,'Konstanten'!$A$6:$A$10,1))),INDEX('Konstanten'!$C$6:$C$10,MATCH($I7,'Konstanten'!$A$6:$A$10,1))),"")) | Q7: =IF(OR($B7="",$N7="",$O7="",$P7=""),"",'Konstanten'!$C$13*$O7*$P7^(1-($J7/1000)/0.075)*'Konstanten'!$C$14^'Konstanten'!$C$16*'Konstanten'!$C$15^'Konstanten'!$C$17*$N7) | R7: =IF(OR($B7="",$Q7=""),"",$E7+$Q7/'Grundeinstellungen'!$J$6) | S7: =IF($B7="","",IFERROR(VLOOKUP($M7,'Konstanten'!$H$6:$I$13,2,FALSE),29)) | T7: =IF(OR($B7="",$Q7=""),"",$Q7*$H7) | U7: =IF(OR($B7="",$T7=""),"",$T7-$F7) | V7: =IF(OR($B7="",$T7=""),"",IFERROR($T7/$F7,"")) | W7: =IF(OR($B7="",$H7=""),"",'Grundeinstellungen'!$J$13*$H7) | X7: =IF(OR($B7="",$T7=""),"",MIN($T7,$F7)+$W7) | Y7: =IF($B7="","",IFERROR($H7/($J7/1000),"")) | Z7: =IF($B7="","",IFERROR(2*$L7*$K7,"")) | AA7: =IF(OR($B7="",$Y7="",$Z7=""),"",$Y7+$Z7) | AB7: =IF(OR($B7="",$AA7=""),"",IFERROR($AA7/$K7,"")) | AC7: =IF(OR($B7="",$X7=""),"",IFERROR(($X7/$K7)/('Grundeinstellungen'!$C$16*('Grundeinstellungen'!$C$6-'Grundeinstellungen'!$C$7))*3600,"")) | AD7: =IF(OR($B7="",$AC7=""),"",$AC7/'Grundeinstellungen'!$C$15*1000) | AE7: =IF(OR($B7="",$AC7=""),"",IFERROR($AC7/3600/'Grundeinstellungen'!$C$15/'Grundeinstellungen'!$J$22,"")) | AF7: =IF(OR($B7="",$AE7=""),"",IFERROR($AE7*'Grundeinstellungen'!$J$21/'Grundeinstellungen'!$C$17,"")) | AG7: =IF(OR($B7="",$AF7=""),"",IF($AF7<2300,"laminar",IF($AF7<4000,"Übergangsbereich","turbulent"))) | AH7: =IF(OR($B7="",$AF7=""),"",IF($AF7<2300,64/$AF7,0.316/$AF7^0.25)) | AI7: =IF(OR($B7="",$AH7="",$AB7=""),"",IFERROR($AH7*($AB7/'Grundeinstellungen'!$J$21)*('Grundeinstellungen'!$C$15/2)*$AE7^2,"")) | AJ7: =IF(OR($B7="",$AI7="",$AB7=""),"",IFERROR($AI7/$AB7,"")) | AK7: =IF(OR($B7="",$AI7=""),"",$AI7*(1+'Grundeinstellungen'!$C$24)+'Grundeinstellungen'!$C$25)
A8: HKV EG | B8: 002 | C8: Großraumbüro | D8: 60 | E8: 20 | F8: 2400 | G8: =IF($B8="","",IFERROR($F8/$D8,"")) | H8: 55 | I8: 0.1 | J8: 150 | K8: 4 | L8: 8 | M8: AZ | N8: =IF($B8="","",IFERROR(('Grundeinstellungen'!$C$6-'Grundeinstellungen'!$C$7)/LN(('Grundeinstellungen'!$C$6-$E8)/('Grundeinstellungen'!$C$7-$E8)),"")) | O8: =IF($B8="","",IFERROR(IFERROR(INDEX('Konstanten'!$B$6:$B$10,MATCH($I8,'Konstanten'!$A$6:$A$10,1))+($I8-INDEX('Konstanten'!$A$6:$A$10,MATCH($I8,'Konstanten'!$A$6:$A$10,1)))/(INDEX('Konstanten'!$A$6:$A$10,MATCH($I8,'Konstanten'!$A$6:$A$10,1)+1)-INDEX('Konstanten'!$A$6:$A$10,MATCH($I8,'Konstanten'!$A$6:$A$10,1)))*(INDEX('Konstanten'!$B$6:$B$10,MATCH($I8,'Konstanten'!$A$6:$A$10,1)+1)-INDEX('Konstanten'!$B$6:$B$10,MATCH($I8,'Konstanten'!$A$6:$A$10,1))),INDEX('Konstanten'!$B$6:$B$10,MATCH($I8,'Konstanten'!$A$6:$A$10,1))),"")) | P8: =IF($B8="","",IFERROR(IFERROR(INDEX('Konstanten'!$C$6:$C$10,MATCH($I8,'Konstanten'!$A$6:$A$10,1))+($I8-INDEX('Konstanten'!$A$6:$A$10,MATCH($I8,'Konstanten'!$A$6:$A$10,1)))/(INDEX('Konstanten'!$A$6:$A$10,MATCH($I8,'Konstanten'!$A$6:$A$10,1)+1)-INDEX('Konstanten'!$A$6:$A$10,MATCH($I8,'Konstanten'!$A$6:$A$10,1)))*(INDEX('Konstanten'!$C$6:$C$10,MATCH($I8,'Konstanten'!$A$6:$A$10,1)+1)-INDEX('Konstanten'!$C$6:$C$10,MATCH($I8,'Konstanten'!$A$6:$A$10,1))),INDEX('Konstanten'!$C$6:$C$10,MATCH($I8,'Konstanten'!$A$6:$A$10,1))),"")) | Q8: =IF(OR($B8="",$N8="",$O8="",$P8=""),"",'Konstanten'!$C$13*$O8*$P8^(1-($J8/1000)/0.075)*'Konstanten'!$C$14^'Konstanten'!$C$16*'Konstanten'!$C$15^'Konstanten'!$C$17*$N8) | R8: =IF(OR($B8="",$Q8=""),"",$E8+$Q8/'Grundeinstellungen'!$J$6) | S8: =IF($B8="","",IFERROR(VLOOKUP($M8,'Konstanten'!$H$6:$I$13,2,FALSE),29)) | T8: =IF(OR($B8="",$Q8=""),"",$Q8*$H8) | U8: =IF(OR($B8="",$T8=""),"",$T8-$F8) | V8: =IF(OR($B8="",$T8=""),"",IFERROR($T8/$F8,"")) | W8: =IF(OR($B8="",$H8=""),"",'Grundeinstellungen'!$J$13*$H8) | X8: =IF(OR($B8="",$T8=""),"",MIN($T8,$F8)+$W8) | Y8: =IF($B8="","",IFERROR($H8/($J8/1000),"")) | Z8: =IF($B8="","",IFERROR(2*$L8*$K8,"")) | AA8: =IF(OR($B8="",$Y8="",$Z8=""),"",$Y8+$Z8) | AB8: =IF(OR($B8="",$AA8=""),"",IFERROR($AA8/$K8,"")) | AC8: =IF(OR($B8="",$X8=""),"",IFERROR(($X8/$K8)/('Grundeinstellungen'!$C$16*('Grundeinstellungen'!$C$6-'Grundeinstellungen'!$C$7))*3600,"")) | AD8: =IF(OR($B8="",$AC8=""),"",$AC8/'Grundeinstellungen'!$C$15*1000) | AE8: =IF(OR($B8="",$AC8=""),"",IFERROR($AC8/3600/'Grundeinstellungen'!$C$15/'Grundeinstellungen'!$J$22,"")) | AF8: =IF(OR($B8="",$AE8=""),"",IFERROR($AE8*'Grundeinstellungen'!$J$21/'Grundeinstellungen'!$C$17,"")) | AG8: =IF(OR($B8="",$AF8=""),"",IF($AF8<2300,"laminar",IF($AF8<4000,"Übergangsbereich","turbulent"))) | AH8: =IF(OR($B8="",$AF8=""),"",IF($AF8<2300,64/$AF8,0.316/$AF8^0.25)) | AI8: =IF(OR($B8="",$AH8="",$AB8=""),"",IFERROR($AH8*($AB8/'Grundeinstellungen'!$J$21)*('Grundeinstellungen'!$C$15/2)*$AE8^2,"")) | AJ8: =IF(OR($B8="",$AI8="",$AB8=""),"",IFERROR($AI8/$AB8,"")) | AK8: =IF(OR($B8="",$AI8=""),"",$AI8*(1+'Grundeinstellungen'!$C$24)+'Grundeinstellungen'!$C$25)
A9: HKV EG | B9: 003 | C9: Büro 1 | D9: 18 | E9: 20 | F9: 630 | G9: =IF($B9="","",IFERROR($F9/$D9,"")) | H9: 16 | I9: 0.1 | J9: 150 | K9: 1 | L9: 5 | M9: AZ | N9: =IF($B9="","",IFERROR(('Grundeinstellungen'!$C$6-'Grundeinstellungen'!$C$7)/LN(('Grundeinstellungen'!$C$6-$E9)/('Grundeinstellungen'!$C$7-$E9)),"")) | O9: =IF($B9="","",IFERROR(IFERROR(INDEX('Konstanten'!$B$6:$B$10,MATCH($I9,'Konstanten'!$A$6:$A$10,1))+($I9-INDEX('Konstanten'!$A$6:$A$10,MATCH($I9,'Konstanten'!$A$6:$A$10,1)))/(INDEX('Konstanten'!$A$6:$A$10,MATCH($I9,'Konstanten'!$A$6:$A$10,1)+1)-INDEX('Konstanten'!$A$6:$A$10,MATCH($I9,'Konstanten'!$A$6:$A$10,1)))*(INDEX('Konstanten'!$B$6:$B$10,MATCH($I9,'Konstanten'!$A$6:$A$10,1)+1)-INDEX('Konstanten'!$B$6:$B$10,MATCH($I9,'Konstanten'!$A$6:$A$10,1))),INDEX('Konstanten'!$B$6:$B$10,MATCH($I9,'Konstanten'!$A$6:$A$10,1))),"")) | P9: =IF($B9="","",IFERROR(IFERROR(INDEX('Konstanten'!$C$6:$C$10,MATCH($I9,'Konstanten'!$A$6:$A$10,1))+($I9-INDEX('Konstanten'!$A$6:$A$10,MATCH($I9,'Konstanten'!$A$6:$A$10,1)))/(INDEX('Konstanten'!$A$6:$A$10,MATCH($I9,'Konstanten'!$A$6:$A$10,1)+1)-INDEX('Konstanten'!$A$6:$A$10,MATCH($I9,'Konstanten'!$A$6:$A$10,1)))*(INDEX('Konstanten'!$C$6:$C$10,MATCH($I9,'Konstanten'!$A$6:$A$10,1)+1)-INDEX('Konstanten'!$C$6:$C$10,MATCH($I9,'Konstanten'!$A$6:$A$10,1))),INDEX('Konstanten'!$C$6:$C$10,MATCH($I9,'Konstanten'!$A$6:$A$10,1))),"")) | Q9: =IF(OR($B9="",$N9="",$O9="",$P9=""),"",'Konstanten'!$C$13*$O9*$P9^(1-($J9/1000)/0.075)*'Konstanten'!$C$14^'Konstanten'!$C$16*'Konstanten'!$C$15^'Konstanten'!$C$17*$N9) | R9: =IF(OR($B9="",$Q9=""),"",$E9+$Q9/'Grundeinstellungen'!$J$6) | S9: =IF($B9="","",IFERROR(VLOOKUP($M9,'Konstanten'!$H$6:$I$13,2,FALSE),29)) | T9: =IF(OR($B9="",$Q9=""),"",$Q9*$H9) | U9: =IF(OR($B9="",$T9=""),"",$T9-$F9) | V9: =IF(OR($B9="",$T9=""),"",IFERROR($T9/$F9,"")) | W9: =IF(OR($B9="",$H9=""),"",'Grundeinstellungen'!$J$13*$H9) | X9: =IF(OR($B9="",$T9=""),"",MIN($T9,$F9)+$W9) | Y9: =IF($B9="","",IFERROR($H9/($J9/1000),"")) | Z9: =IF($B9="","",IFERROR(2*$L9*$K9,"")) | AA9: =IF(OR($B9="",$Y9="",$Z9=""),"",$Y9+$Z9) | AB9: =IF(OR($B9="",$AA9=""),"",IFERROR($AA9/$K9,"")) | AC9: =IF(OR($B9="",$X9=""),"",IFERROR(($X9/$K9)/('Grundeinstellungen'!$C$16*('Grundeinstellungen'!$C$6-'Grundeinstellungen'!$C$7))*3600,"")) | AD9: =IF(OR($B9="",$AC9=""),"",$AC9/'Grundeinstellungen'!$C$15*1000) | AE9: =IF(OR($B9="",$AC9=""),"",IFERROR($AC9/3600/'Grundeinstellungen'!$C$15/'Grundeinstellungen'!$J$22,"")) | AF9: =IF(OR($B9="",$AE9=""),"",IFERROR($AE9*'Grundeinstellungen'!$J$21/'Grundeinstellungen'!$C$17,"")) | AG9: =IF(OR($B9="",$AF9=""),"",IF($AF9<2300,"laminar",IF($AF9<4000,"Übergangsbereich","turbulent"))) | AH9: =IF(OR($B9="",$AF9=""),"",IF($AF9<2300,64/$AF9,0.316/$AF9^0.25)) | AI9: =IF(OR($B9="",$AH9="",$AB9=""),"",IFERROR($AH9*($AB9/'Grundeinstellungen'!$J$21)*('Grundeinstellungen'!$C$15/2)*$AE9^2,"")) | AJ9: =IF(OR($B9="",$AI9="",$AB9=""),"",IFERROR($AI9/$AB9,"")) | AK9: =IF(OR($B9="",$AI9=""),"",$AI9*(1+'Grundeinstellungen'!$C$24)+'Grundeinstellungen'!$C$25)
A10: HKV EG | B10: 004 | C10: Besprechung | D10: 30 | E10: 20 | F10: 1500 | G10: =IF($B10="","",IFERROR($F10/$D10,"")) | H10: 28 | I10: 0.075 | J10: 100 | K10: 2 | L10: 7 | M10: AZ | N10: =IF($B10="","",IFERROR(('Grundeinstellungen'!$C$6-'Grundeinstellungen'!$C$7)/LN(('Grundeinstellungen'!$C$6-$E10)/('Grundeinstellungen'!$C$7-$E10)),"")) | O10: =IF($B10="","",IFERROR(IFERROR(INDEX('Konstanten'!$B$6:$B$10,MATCH($I10,'Konstanten'!$A$6:$A$10,1))+($I10-INDEX('Konstanten'!$A$6:$A$10,MATCH($I10,'Konstanten'!$A$6:$A$10,1)))/(INDEX('Konstanten'!$A$6:$A$10,MATCH($I10,'Konstanten'!$A$6:$A$10,1)+1)-INDEX('Konstanten'!$A$6:$A$10,MATCH($I10,'Konstanten'!$A$6:$A$10,1)))*(INDEX('Konstanten'!$B$6:$B$10,MATCH($I10,'Konstanten'!$A$6:$A$10,1)+1)-INDEX('Konstanten'!$B$6:$B$10,MATCH($I10,'Konstanten'!$A$6:$A$10,1))),INDEX('Konstanten'!$B$6:$B$10,MATCH($I10,'Konstanten'!$A$6:$A$10,1))),"")) | P10: =IF($B10="","",IFERROR(IFERROR(INDEX('Konstanten'!$C$6:$C$10,MATCH($I10,'Konstanten'!$A$6:$A$10,1))+($I10-INDEX('Konstanten'!$A$6:$A$10,MATCH($I10,'Konstanten'!$A$6:$A$10,1)))/(INDEX('Konstanten'!$A$6:$A$10,MATCH($I10,'Konstanten'!$A$6:$A$10,1)+1)-INDEX('Konstanten'!$A$6:$A$10,MATCH($I10,'Konstanten'!$A$6:$A$10,1)))*(INDEX('Konstanten'!$C$6:$C$10,MATCH($I10,'Konstanten'!$A$6:$A$10,1)+1)-INDEX('Konstanten'!$C$6:$C$10,MATCH($I10,'Konstanten'!$A$6:$A$10,1))),INDEX('Konstanten'!$C$6:$C$10,MATCH($I10,'Konstanten'!$A$6:$A$10,1))),"")) | Q10: =IF(OR($B10="",$N10="",$O10="",$P10=""),"",'Konstanten'!$C$13*$O10*$P10^(1-($J10/1000)/0.075)*'Konstanten'!$C$14^'Konstanten'!$C$16*'Konstanten'!$C$15^'Konstanten'!$C$17*$N10) | R10: =IF(OR($B10="",$Q10=""),"",$E10+$Q10/'Grundeinstellungen'!$J$6) | S10: =IF($B10="","",IFERROR(VLOOKUP($M10,'Konstanten'!$H$6:$I$13,2,FALSE),29)) | T10: =IF(OR($B10="",$Q10=""),"",$Q10*$H10) | U10: =IF(OR($B10="",$T10=""),"",$T10-$F10) | V10: =IF(OR($B10="",$T10=""),"",IFERROR($T10/$F10,"")) | W10: =IF(OR($B10="",$H10=""),"",'Grundeinstellungen'!$J$13*$H10) | X10: =IF(OR($B10="",$T10=""),"",MIN($T10,$F10)+$W10) | Y10: =IF($B10="","",IFERROR($H10/($J10/1000),"")) | Z10: =IF($B10="","",IFERROR(2*$L10*$K10,"")) | AA10: =IF(OR($B10="",$Y10="",$Z10=""),"",$Y10+$Z10) | AB10: =IF(OR($B10="",$AA10=""),"",IFERROR($AA10/$K10,"")) | AC10: =IF(OR($B10="",$X10=""),"",IFERROR(($X10/$K10)/('Grundeinstellungen'!$C$16*('Grundeinstellungen'!$C$6-'Grundeinstellungen'!$C$7))*3600,"")) | AD10: =IF(OR($B10="",$AC10=""),"",$AC10/'Grundeinstellungen'!$C$15*1000) | AE10: =IF(OR($B10="",$AC10=""),"",IFERROR($AC10/3600/'Grundeinstellungen'!$C$15/'Grundeinstellungen'!$J$22,"")) | AF10: =IF(OR($B10="",$AE10=""),"",IFERROR($AE10*'Grundeinstellungen'!$J$21/'Grundeinstellungen'!$C$17,"")) | AG10: =IF(OR($B10="",$AF10=""),"",IF($AF10<2300,"laminar",IF($AF10<4000,"Übergangsbereich","turbulent"))) | AH10: =IF(OR($B10="",$AF10=""),"",IF($AF10<2300,64/$AF10,0.316/$AF10^0.25)) | AI10: =IF(OR($B10="",$AH10="",$AB10=""),"",IFERROR($AH10*($AB10/'Grundeinstellungen'!$J$21)*('Grundeinstellungen'!$C$15/2)*$AE10^2,"")) | AJ10: =IF(OR($B10="",$AI10="",$AB10=""),"",IFERROR($AI10/$AB10,"")) | AK10: =IF(OR($B10="",$AI10=""),"",$AI10*(1+'Grundeinstellungen'!$C$24)+'Grundeinstellungen'!$C$25)
A11: HKV EG | B11: 005 | C11: Flur | D11: 25 | E11: 20 | F11: 750 | G11: =IF($B11="","",IFERROR($F11/$D11,"")) | H11: 22 | I11: 0.05 | J11: 200 | K11: 1 | L11: 3 | M11: AZ | N11: =IF($B11="","",IFERROR(('Grundeinstellungen'!$C$6-'Grundeinstellungen'!$C$7)/LN(('Grundeinstellungen'!$C$6-$E11)/('Grundeinstellungen'!$C$7-$E11)),"")) | O11: =IF($B11="","",IFERROR(IFERROR(INDEX('Konstanten'!$B$6:$B$10,MATCH($I11,'Konstanten'!$A$6:$A$10,1))+($I11-INDEX('Konstanten'!$A$6:$A$10,MATCH($I11,'Konstanten'!$A$6:$A$10,1)))/(INDEX('Konstanten'!$A$6:$A$10,MATCH($I11,'Konstanten'!$A$6:$A$10,1)+1)-INDEX('Konstanten'!$A$6:$A$10,MATCH($I11,'Konstanten'!$A$6:$A$10,1)))*(INDEX('Konstanten'!$B$6:$B$10,MATCH($I11,'Konstanten'!$A$6:$A$10,1)+1)-INDEX('Konstanten'!$B$6:$B$10,MATCH($I11,'Konstanten'!$A$6:$A$10,1))),INDEX('Konstanten'!$B$6:$B$10,MATCH($I11,'Konstanten'!$A$6:$A$10,1))),"")) | P11: =IF($B11="","",IFERROR(IFERROR(INDEX('Konstanten'!$C$6:$C$10,MATCH($I11,'Konstanten'!$A$6:$A$10,1))+($I11-INDEX('Konstanten'!$A$6:$A$10,MATCH($I11,'Konstanten'!$A$6:$A$10,1)))/(INDEX('Konstanten'!$A$6:$A$10,MATCH($I11,'Konstanten'!$A$6:$A$10,1)+1)-INDEX('Konstanten'!$A$6:$A$10,MATCH($I11,'Konstanten'!$A$6:$A$10,1)))*(INDEX('Konstanten'!$C$6:$C$10,MATCH($I11,'Konstanten'!$A$6:$A$10,1)+1)-INDEX('Konstanten'!$C$6:$C$10,MATCH($I11,'Konstanten'!$A$6:$A$10,1))),INDEX('Konstanten'!$C$6:$C$10,MATCH($I11,'Konstanten'!$A$6:$A$10,1))),"")) | Q11: =IF(OR($B11="",$N11="",$O11="",$P11=""),"",'Konstanten'!$C$13*$O11*$P11^(1-($J11/1000)/0.075)*'Konstanten'!$C$14^'Konstanten'!$C$16*'Konstanten'!$C$15^'Konstanten'!$C$17*$N11) | R11: =IF(OR($B11="",$Q11=""),"",$E11+$Q11/'Grundeinstellungen'!$J$6) | S11: =IF($B11="","",IFERROR(VLOOKUP($M11,'Konstanten'!$H$6:$I$13,2,FALSE),29)) | T11: =IF(OR($B11="",$Q11=""),"",$Q11*$H11) | U11: =IF(OR($B11="",$T11=""),"",$T11-$F11) | V11: =IF(OR($B11="",$T11=""),"",IFERROR($T11/$F11,"")) | W11: =IF(OR($B11="",$H11=""),"",'Grundeinstellungen'!$J$13*$H11) | X11: =IF(OR($B11="",$T11=""),"",MIN($T11,$F11)+$W11) | Y11: =IF($B11="","",IFERROR($H11/($J11/1000),"")) | Z11: =IF($B11="","",IFERROR(2*$L11*$K11,"")) | AA11: =IF(OR($B11="",$Y11="",$Z11=""),"",$Y11+$Z11) | AB11: =IF(OR($B11="",$AA11=""),"",IFERROR($AA11/$K11,"")) | AC11: =IF(OR($B11="",$X11=""),"",IFERROR(($X11/$K11)/('Grundeinstellungen'!$C$16*('Grundeinstellungen'!$C$6-'Grundeinstellungen'!$C$7))*3600,"")) | AD11: =IF(OR($B11="",$AC11=""),"",$AC11/'Grundeinstellungen'!$C$15*1000) | AE11: =IF(OR($B11="",$AC11=""),"",IFERROR($AC11/3600/'Grundeinstellungen'!$C$15/'Grundeinstellungen'!$J$22,"")) | AF11: =IF(OR($B11="",$AE11=""),"",IFERROR($AE11*'Grundeinstellungen'!$J$21/'Grundeinstellungen'!$C$17,"")) | AG11: =IF(OR($B11="",$AF11=""),"",IF($AF11<2300,"laminar",IF($AF11<4000,"Übergangsbereich","turbulent"))) | AH11: =IF(OR($B11="",$AF11=""),"",IF($AF11<2300,64/$AF11,0.316/$AF11^0.25)) | AI11: =IF(OR($B11="",$AH11="",$AB11=""),"",IFERROR($AH11*($AB11/'Grundeinstellungen'!$J$21)*('Grundeinstellungen'!$C$15/2)*$AE11^2,"")) | AJ11: =IF(OR($B11="",$AI11="",$AB11=""),"",IFERROR($AI11/$AB11,"")) | AK11: =IF(OR($B11="",$AI11=""),"",$AI11*(1+'Grundeinstellungen'!$C$24)+'Grundeinstellungen'!$C$25)
A12: HKV OG | B12: 101 | C12: WC / Sanitär | D12: 12 | E12: 24 | F12: 600 | G12: =IF($B12="","",IFERROR($F12/$D12,"")) | H12: 9 | I12: 0.01 | J12: 100 | K12: 1 | L12: 10 | M12: BAD | N12: =IF($B12="","",IFERROR(('Grundeinstellungen'!$C$6-'Grundeinstellungen'!$C$7)/LN(('Grundeinstellungen'!$C$6-$E12)/('Grundeinstellungen'!$C$7-$E12)),"")) | O12: =IF($B12="","",IFERROR(IFERROR(INDEX('Konstanten'!$B$6:$B$10,MATCH($I12,'Konstanten'!$A$6:$A$10,1))+($I12-INDEX('Konstanten'!$A$6:$A$10,MATCH($I12,'Konstanten'!$A$6:$A$10,1)))/(INDEX('Konstanten'!$A$6:$A$10,MATCH($I12,'Konstanten'!$A$6:$A$10,1)+1)-INDEX('Konstanten'!$A$6:$A$10,MATCH($I12,'Konstanten'!$A$6:$A$10,1)))*(INDEX('Konstanten'!$B$6:$B$10,MATCH($I12,'Konstanten'!$A$6:$A$10,1)+1)-INDEX('Konstanten'!$B$6:$B$10,MATCH($I12,'Konstanten'!$A$6:$A$10,1))),INDEX('Konstanten'!$B$6:$B$10,MATCH($I12,'Konstanten'!$A$6:$A$10,1))),"")) | P12: =IF($B12="","",IFERROR(IFERROR(INDEX('Konstanten'!$C$6:$C$10,MATCH($I12,'Konstanten'!$A$6:$A$10,1))+($I12-INDEX('Konstanten'!$A$6:$A$10,MATCH($I12,'Konstanten'!$A$6:$A$10,1)))/(INDEX('Konstanten'!$A$6:$A$10,MATCH($I12,'Konstanten'!$A$6:$A$10,1)+1)-INDEX('Konstanten'!$A$6:$A$10,MATCH($I12,'Konstanten'!$A$6:$A$10,1)))*(INDEX('Konstanten'!$C$6:$C$10,MATCH($I12,'Konstanten'!$A$6:$A$10,1)+1)-INDEX('Konstanten'!$C$6:$C$10,MATCH($I12,'Konstanten'!$A$6:$A$10,1))),INDEX('Konstanten'!$C$6:$C$10,MATCH($I12,'Konstanten'!$A$6:$A$10,1))),"")) | Q12: =IF(OR($B12="",$N12="",$O12="",$P12=""),"",'Konstanten'!$C$13*$O12*$P12^(1-($J12/1000)/0.075)*'Konstanten'!$C$14^'Konstanten'!$C$16*'Konstanten'!$C$15^'Konstanten'!$C$17*$N12) | R12: =IF(OR($B12="",$Q12=""),"",$E12+$Q12/'Grundeinstellungen'!$J$6) | S12: =IF($B12="","",IFERROR(VLOOKUP($M12,'Konstanten'!$H$6:$I$13,2,FALSE),29)) | T12: =IF(OR($B12="",$Q12=""),"",$Q12*$H12) | U12: =IF(OR($B12="",$T12=""),"",$T12-$F12) | V12: =IF(OR($B12="",$T12=""),"",IFERROR($T12/$F12,"")) | W12: =IF(OR($B12="",$H12=""),"",'Grundeinstellungen'!$J$13*$H12) | X12: =IF(OR($B12="",$T12=""),"",MIN($T12,$F12)+$W12) | Y12: =IF($B12="","",IFERROR($H12/($J12/1000),"")) | Z12: =IF($B12="","",IFERROR(2*$L12*$K12,"")) | AA12: =IF(OR($B12="",$Y12="",$Z12=""),"",$Y12+$Z12) | AB12: =IF(OR($B12="",$AA12=""),"",IFERROR($AA12/$K12,"")) | AC12: =IF(OR($B12="",$X12=""),"",IFERROR(($X12/$K12)/('Grundeinstellungen'!$C$16*('Grundeinstellungen'!$C$6-'Grundeinstellungen'!$C$7))*3600,"")) | AD12: =IF(OR($B12="",$AC12=""),"",$AC12/'Grundeinstellungen'!$C$15*1000) | AE12: =IF(OR($B12="",$AC12=""),"",IFERROR($AC12/3600/'Grundeinstellungen'!$C$15/'Grundeinstellungen'!$J$22,"")) | AF12: =IF(OR($B12="",$AE12=""),"",IFERROR($AE12*'Grundeinstellungen'!$J$21/'Grundeinstellungen'!$C$17,"")) | AG12: =IF(OR($B12="",$AF12=""),"",IF($AF12<2300,"laminar",IF($AF12<4000,"Übergangsbereich","turbulent"))) | AH12: =IF(OR($B12="",$AF12=""),"",IF($AF12<2300,64/$AF12,0.316/$AF12^0.25)) | AI12: =IF(OR($B12="",$AH12="",$AB12=""),"",IFERROR($AH12*($AB12/'Grundeinstellungen'!$J$21)*('Grundeinstellungen'!$C$15/2)*$AE12^2,"")) | AJ12: =IF(OR($B12="",$AI12="",$AB12=""),"",IFERROR($AI12/$AB12,"")) | AK12: =IF(OR($B12="",$AI12=""),"",$AI12*(1+'Grundeinstellungen'!$C$24)+'Grundeinstellungen'!$C$25)
A13: HKV OG | B13: 102 | C13: Teeküche | D13: 10 | E13: 20 | F13: 450 | G13: =IF($B13="","",IFERROR($F13/$D13,"")) | H13: 8 | I13: 0.01 | J13: 100 | K13: 1 | L13: 9 | M13: AZ | N13: =IF($B13="","",IFERROR(('Grundeinstellungen'!$C$6-'Grundeinstellungen'!$C$7)/LN(('Grundeinstellungen'!$C$6-$E13)/('Grundeinstellungen'!$C$7-$E13)),"")) | O13: =IF($B13="","",IFERROR(IFERROR(INDEX('Konstanten'!$B$6:$B$10,MATCH($I13,'Konstanten'!$A$6:$A$10,1))+($I13-INDEX('Konstanten'!$A$6:$A$10,MATCH($I13,'Konstanten'!$A$6:$A$10,1)))/(INDEX('Konstanten'!$A$6:$A$10,MATCH($I13,'Konstanten'!$A$6:$A$10,1)+1)-INDEX('Konstanten'!$A$6:$A$10,MATCH($I13,'Konstanten'!$A$6:$A$10,1)))*(INDEX('Konstanten'!$B$6:$B$10,MATCH($I13,'Konstanten'!$A$6:$A$10,1)+1)-INDEX('Konstanten'!$B$6:$B$10,MATCH($I13,'Konstanten'!$A$6:$A$10,1))),INDEX('Konstanten'!$B$6:$B$10,MATCH($I13,'Konstanten'!$A$6:$A$10,1))),"")) | P13: =IF($B13="","",IFERROR(IFERROR(INDEX('Konstanten'!$C$6:$C$10,MATCH($I13,'Konstanten'!$A$6:$A$10,1))+($I13-INDEX('Konstanten'!$A$6:$A$10,MATCH($I13,'Konstanten'!$A$6:$A$10,1)))/(INDEX('Konstanten'!$A$6:$A$10,MATCH($I13,'Konstanten'!$A$6:$A$10,1)+1)-INDEX('Konstanten'!$A$6:$A$10,MATCH($I13,'Konstanten'!$A$6:$A$10,1)))*(INDEX('Konstanten'!$C$6:$C$10,MATCH($I13,'Konstanten'!$A$6:$A$10,1)+1)-INDEX('Konstanten'!$C$6:$C$10,MATCH($I13,'Konstanten'!$A$6:$A$10,1))),INDEX('Konstanten'!$C$6:$C$10,MATCH($I13,'Konstanten'!$A$6:$A$10,1))),"")) | Q13: =IF(OR($B13="",$N13="",$O13="",$P13=""),"",'Konstanten'!$C$13*$O13*$P13^(1-($J13/1000)/0.075)*'Konstanten'!$C$14^'Konstanten'!$C$16*'Konstanten'!$C$15^'Konstanten'!$C$17*$N13) | R13: =IF(OR($B13="",$Q13=""),"",$E13+$Q13/'Grundeinstellungen'!$J$6) | S13: =IF($B13="","",IFERROR(VLOOKUP($M13,'Konstanten'!$H$6:$I$13,2,FALSE),29)) | T13: =IF(OR($B13="",$Q13=""),"",$Q13*$H13) | U13: =IF(OR($B13="",$T13=""),"",$T13-$F13) | V13: =IF(OR($B13="",$T13=""),"",IFERROR($T13/$F13,"")) | W13: =IF(OR($B13="",$H13=""),"",'Grundeinstellungen'!$J$13*$H13) | X13: =IF(OR($B13="",$T13=""),"",MIN($T13,$F13)+$W13) | Y13: =IF($B13="","",IFERROR($H13/($J13/1000),"")) | Z13: =IF($B13="","",IFERROR(2*$L13*$K13,"")) | AA13: =IF(OR($B13="",$Y13="",$Z13=""),"",$Y13+$Z13) | AB13: =IF(OR($B13="",$AA13=""),"",IFERROR($AA13/$K13,"")) | AC13: =IF(OR($B13="",$X13=""),"",IFERROR(($X13/$K13)/('Grundeinstellungen'!$C$16*('Grundeinstellungen'!$C$6-'Grundeinstellungen'!$C$7))*3600,"")) | AD13: =IF(OR($B13="",$AC13=""),"",$AC13/'Grundeinstellungen'!$C$15*1000) | AE13: =IF(OR($B13="",$AC13=""),"",IFERROR($AC13/3600/'Grundeinstellungen'!$C$15/'Grundeinstellungen'!$J$22,"")) | AF13: =IF(OR($B13="",$AE13=""),"",IFERROR($AE13*'Grundeinstellungen'!$J$21/'Grundeinstellungen'!$C$17,"")) | AG13: =IF(OR($B13="",$AF13=""),"",IF($AF13<2300,"laminar",IF($AF13<4000,"Übergangsbereich","turbulent"))) | AH13: =IF(OR($B13="",$AF13=""),"",IF($AF13<2300,64/$AF13,0.316/$AF13^0.25)) | AI13: =IF(OR($B13="",$AH13="",$AB13=""),"",IFERROR($AH13*($AB13/'Grundeinstellungen'!$J$21)*('Grundeinstellungen'!$C$15/2)*$AE13^2,"")) | AJ13: =IF(OR($B13="",$AI13="",$AB13=""),"",IFERROR($AI13/$AB13,"")) | AK13: =IF(OR($B13="",$AI13=""),"",$AI13*(1+'Grundeinstellungen'!$C$24)+'Grundeinstellungen'!$C$25)
A14: HKV OG | B14: 103 | C14: Archiv | D14: 20 | E14: 18 | F14: 500 | G14: =IF($B14="","",IFERROR($F14/$D14,"")) | H14: 18 | I14: 0.05 | J14: 200 | K14: 1 | L14: 12 | M14: AZ | N14: =IF($B14="","",IFERROR(('Grundeinstellungen'!$C$6-'Grundeinstellungen'!$C$7)/LN(('Grundeinstellungen'!$C$6-$E14)/('Grundeinstellungen'!$C$7-$E14)),"")) | O14: =IF($B14="","",IFERROR(IFERROR(INDEX('Konstanten'!$B$6:$B$10,MATCH($I14,'Konstanten'!$A$6:$A$10,1))+($I14-INDEX('Konstanten'!$A$6:$A$10,MATCH($I14,'Konstanten'!$A$6:$A$10,1)))/(INDEX('Konstanten'!$A$6:$A$10,MATCH($I14,'Konstanten'!$A$6:$A$10,1)+1)-INDEX('Konstanten'!$A$6:$A$10,MATCH($I14,'Konstanten'!$A$6:$A$10,1)))*(INDEX('Konstanten'!$B$6:$B$10,MATCH($I14,'Konstanten'!$A$6:$A$10,1)+1)-INDEX('Konstanten'!$B$6:$B$10,MATCH($I14,'Konstanten'!$A$6:$A$10,1))),INDEX('Konstanten'!$B$6:$B$10,MATCH($I14,'Konstanten'!$A$6:$A$10,1))),"")) | P14: =IF($B14="","",IFERROR(IFERROR(INDEX('Konstanten'!$C$6:$C$10,MATCH($I14,'Konstanten'!$A$6:$A$10,1))+($I14-INDEX('Konstanten'!$A$6:$A$10,MATCH($I14,'Konstanten'!$A$6:$A$10,1)))/(INDEX('Konstanten'!$A$6:$A$10,MATCH($I14,'Konstanten'!$A$6:$A$10,1)+1)-INDEX('Konstanten'!$A$6:$A$10,MATCH($I14,'Konstanten'!$A$6:$A$10,1)))*(INDEX('Konstanten'!$C$6:$C$10,MATCH($I14,'Konstanten'!$A$6:$A$10,1)+1)-INDEX('Konstanten'!$C$6:$C$10,MATCH($I14,'Konstanten'!$A$6:$A$10,1))),INDEX('Konstanten'!$C$6:$C$10,MATCH($I14,'Konstanten'!$A$6:$A$10,1))),"")) | Q14: =IF(OR($B14="",$N14="",$O14="",$P14=""),"",'Konstanten'!$C$13*$O14*$P14^(1-($J14/1000)/0.075)*'Konstanten'!$C$14^'Konstanten'!$C$16*'Konstanten'!$C$15^'Konstanten'!$C$17*$N14) | R14: =IF(OR($B14="",$Q14=""),"",$E14+$Q14/'Grundeinstellungen'!$J$6) | S14: =IF($B14="","",IFERROR(VLOOKUP($M14,'Konstanten'!$H$6:$I$13,2,FALSE),29)) | T14: =IF(OR($B14="",$Q14=""),"",$Q14*$H14) | U14: =IF(OR($B14="",$T14=""),"",$T14-$F14) | V14: =IF(OR($B14="",$T14=""),"",IFERROR($T14/$F14,"")) | W14: =IF(OR($B14="",$H14=""),"",'Grundeinstellungen'!$J$13*$H14) | X14: =IF(OR($B14="",$T14=""),"",MIN($T14,$F14)+$W14) | Y14: =IF($B14="","",IFERROR($H14/($J14/1000),"")) | Z14: =IF($B14="","",IFERROR(2*$L14*$K14,"")) | AA14: =IF(OR($B14="",$Y14="",$Z14=""),"",$Y14+$Z14) | AB14: =IF(OR($B14="",$AA14=""),"",IFERROR($AA14/$K14,"")) | AC14: =IF(OR($B14="",$X14=""),"",IFERROR(($X14/$K14)/('Grundeinstellungen'!$C$16*('Grundeinstellungen'!$C$6-'Grundeinstellungen'!$C$7))*3600,"")) | AD14: =IF(OR($B14="",$AC14=""),"",$AC14/'Grundeinstellungen'!$C$15*1000) | AE14: =IF(OR($B14="",$AC14=""),"",IFERROR($AC14/3600/'Grundeinstellungen'!$C$15/'Grundeinstellungen'!$J$22,"")) | AF14: =IF(OR($B14="",$AE14=""),"",IFERROR($AE14*'Grundeinstellungen'!$J$21/'Grundeinstellungen'!$C$17,"")) | AG14: =IF(OR($B14="",$AF14=""),"",IF($AF14<2300,"laminar",IF($AF14<4000,"Übergangsbereich","turbulent"))) | AH14: =IF(OR($B14="",$AF14=""),"",IF($AF14<2300,64/$AF14,0.316/$AF14^0.25)) | AI14: =IF(OR($B14="",$AH14="",$AB14=""),"",IFERROR($AH14*($AB14/'Grundeinstellungen'!$J$21)*('Grundeinstellungen'!$C$15/2)*$AE14^2,"")) | AJ14: =IF(OR($B14="",$AI14="",$AB14=""),"",IFERROR($AI14/$AB14,"")) | AK14: =IF(OR($B14="",$AI14=""),"",$AI14*(1+'Grundeinstellungen'!$C$24)+'Grundeinstellungen'!$C$25)
A15: HKV OG | B15: 104 | C15: Technikraum | D15: 15 | E15: 15 | F15: 300 | G15: =IF($B15="","",IFERROR($F15/$D15,"")) | H15: 12 | I15: 0 | J15: 250 | K15: 1 | L15: 14 | M15: AZ | N15: =IF($B15="","",IFERROR(('Grundeinstellungen'!$C$6-'Grundeinstellungen'!$C$7)/LN(('Grundeinstellungen'!$C$6-$E15)/('Grundeinstellungen'!$C$7-$E15)),"")) | O15: =IF($B15="","",IFERROR(IFERROR(INDEX('Konstanten'!$B$6:$B$10,MATCH($I15,'Konstanten'!$A$6:$A$10,1))+($I15-INDEX('Konstanten'!$A$6:$A$10,MATCH($I15,'Konstanten'!$A$6:$A$10,1)))/(INDEX('Konstanten'!$A$6:$A$10,MATCH($I15,'Konstanten'!$A$6:$A$10,1)+1)-INDEX('Konstanten'!$A$6:$A$10,MATCH($I15,'Konstanten'!$A$6:$A$10,1)))*(INDEX('Konstanten'!$B$6:$B$10,MATCH($I15,'Konstanten'!$A$6:$A$10,1)+1)-INDEX('Konstanten'!$B$6:$B$10,MATCH($I15,'Konstanten'!$A$6:$A$10,1))),INDEX('Konstanten'!$B$6:$B$10,MATCH($I15,'Konstanten'!$A$6:$A$10,1))),"")) | P15: =IF($B15="","",IFERROR(IFERROR(INDEX('Konstanten'!$C$6:$C$10,MATCH($I15,'Konstanten'!$A$6:$A$10,1))+($I15-INDEX('Konstanten'!$A$6:$A$10,MATCH($I15,'Konstanten'!$A$6:$A$10,1)))/(INDEX('Konstanten'!$A$6:$A$10,MATCH($I15,'Konstanten'!$A$6:$A$10,1)+1)-INDEX('Konstanten'!$A$6:$A$10,MATCH($I15,'Konstanten'!$A$6:$A$10,1)))*(INDEX('Konstanten'!$C$6:$C$10,MATCH($I15,'Konstanten'!$A$6:$A$10,1)+1)-INDEX('Konstanten'!$C$6:$C$10,MATCH($I15,'Konstanten'!$A$6:$A$10,1))),INDEX('Konstanten'!$C$6:$C$10,MATCH($I15,'Konstanten'!$A$6:$A$10,1))),"")) | Q15: =IF(OR($B15="",$N15="",$O15="",$P15=""),"",'Konstanten'!$C$13*$O15*$P15^(1-($J15/1000)/0.075)*'Konstanten'!$C$14^'Konstanten'!$C$16*'Konstanten'!$C$15^'Konstanten'!$C$17*$N15) | R15: =IF(OR($B15="",$Q15=""),"",$E15+$Q15/'Grundeinstellungen'!$J$6) | S15: =IF($B15="","",IFERROR(VLOOKUP($M15,'Konstanten'!$H$6:$I$13,2,FALSE),29)) | T15: =IF(OR($B15="",$Q15=""),"",$Q15*$H15) | U15: =IF(OR($B15="",$T15=""),"",$T15-$F15) | V15: =IF(OR($B15="",$T15=""),"",IFERROR($T15/$F15,"")) | W15: =IF(OR($B15="",$H15=""),"",'Grundeinstellungen'!$J$13*$H15) | X15: =IF(OR($B15="",$T15=""),"",MIN($T15,$F15)+$W15) | Y15: =IF($B15="","",IFERROR($H15/($J15/1000),"")) | Z15: =IF($B15="","",IFERROR(2*$L15*$K15,"")) | AA15: =IF(OR($B15="",$Y15="",$Z15=""),"",$Y15+$Z15) | AB15: =IF(OR($B15="",$AA15=""),"",IFERROR($AA15/$K15,"")) | AC15: =IF(OR($B15="",$X15=""),"",IFERROR(($X15/$K15)/('Grundeinstellungen'!$C$16*('Grundeinstellungen'!$C$6-'Grundeinstellungen'!$C$7))*3600,"")) | AD15: =IF(OR($B15="",$AC15=""),"",$AC15/'Grundeinstellungen'!$C$15*1000) | AE15: =IF(OR($B15="",$AC15=""),"",IFERROR($AC15/3600/'Grundeinstellungen'!$C$15/'Grundeinstellungen'!$J$22,"")) | AF15: =IF(OR($B15="",$AE15=""),"",IFERROR($AE15*'Grundeinstellungen'!$J$21/'Grundeinstellungen'!$C$17,"")) | AG15: =IF(OR($B15="",$AF15=""),"",IF($AF15<2300,"laminar",IF($AF15<4000,"Übergangsbereich","turbulent"))) | AH15: =IF(OR($B15="",$AF15=""),"",IF($AF15<2300,64/$AF15,0.316/$AF15^0.25)) | AI15: =IF(OR($B15="",$AH15="",$AB15=""),"",IFERROR($AH15*($AB15/'Grundeinstellungen'!$J$21)*('Grundeinstellungen'!$C$15/2)*$AE15^2,"")) | AJ15: =IF(OR($B15="",$AI15="",$AB15=""),"",IFERROR($AI15/$AB15,"")) | AK15: =IF(OR($B15="",$AI15=""),"",$AI15*(1+'Grundeinstellungen'!$C$24)+'Grundeinstellungen'!$C$25)
G16: =IF($B16="","",IFERROR($F16/$D16,"")) | N16: =IF($B16="","",IFERROR(('Grundeinstellungen'!$C$6-'Grundeinstellungen'!$C$7)/LN(('Grundeinstellungen'!$C$6-$E16)/('Grundeinstellungen'!$C$7-$E16)),"")) | O16: =IF($B16="","",IFERROR(IFERROR(INDEX('Konstanten'!$B$6:$B$10,MATCH($I16,'Konstanten'!$A$6:$A$10,1))+($I16-INDEX('Konstanten'!$A$6:$A$10,MATCH($I16,'Konstanten'!$A$6:$A$10,1)))/(INDEX('Konstanten'!$A$6:$A$10,MATCH($I16,'Konstanten'!$A$6:$A$10,1)+1)-INDEX('Konstanten'!$A$6:$A$10,MATCH($I16,'Konstanten'!$A$6:$A$10,1)))*(INDEX('Konstanten'!$B$6:$B$10,MATCH($I16,'Konstanten'!$A$6:$A$10,1)+1)-INDEX('Konstanten'!$B$6:$B$10,MATCH($I16,'Konstanten'!$A$6:$A$10,1))),INDEX('Konstanten'!$B$6:$B$10,MATCH($I16,'Konstanten'!$A$6:$A$10,1))),"")) | P16: =IF($B16="","",IFERROR(IFERROR(INDEX('Konstanten'!$C$6:$C$10,MATCH($I16,'Konstanten'!$A$6:$A$10,1))+($I16-INDEX('Konstanten'!$A$6:$A$10,MATCH($I16,'Konstanten'!$A$6:$A$10,1)))/(INDEX('Konstanten'!$A$6:$A$10,MATCH($I16,'Konstanten'!$A$6:$A$10,1)+1)-INDEX('Konstanten'!$A$6:$A$10,MATCH($I16,'Konstanten'!$A$6:$A$10,1)))*(INDEX('Konstanten'!$C$6:$C$10,MATCH($I16,'Konstanten'!$A$6:$A$10,1)+1)-INDEX('Konstanten'!$C$6:$C$10,MATCH($I16,'Konstanten'!$A$6:$A$10,1))),INDEX('Konstanten'!$C$6:$C$10,MATCH($I16,'Konstanten'!$A$6:$A$10,1))),"")) | Q16: =IF(OR($B16="",$N16="",$O16="",$P16=""),"",'Konstanten'!$C$13*$O16*$P16^(1-($J16/1000)/0.075)*'Konstanten'!$C$14^'Konstanten'!$C$16*'Konstanten'!$C$15^'Konstanten'!$C$17*$N16) | R16: =IF(OR($B16="",$Q16=""),"",$E16+$Q16/'Grundeinstellungen'!$J$6) | S16: =IF($B16="","",IFERROR(VLOOKUP($M16,'Konstanten'!$H$6:$I$13,2,FALSE),29)) | T16: =IF(OR($B16="",$Q16=""),"",$Q16*$H16) | U16: =IF(OR($B16="",$T16=""),"",$T16-$F16) | V16: =IF(OR($B16="",$T16=""),"",IFERROR($T16/$F16,"")) | W16: =IF(OR($B16="",$H16=""),"",'Grundeinstellungen'!$J$13*$H16) | X16: =IF(OR($B16="",$T16=""),"",MIN($T16,$F16)+$W16) | Y16: =IF($B16="","",IFERROR($H16/($J16/1000),"")) | Z16: =IF($B16="","",IFERROR(2*$L16*$K16,"")) | AA16: =IF(OR($B16="",$Y16="",$Z16=""),"",$Y16+$Z16) | AB16: =IF(OR($B16="",$AA16=""),"",IFERROR($AA16/$K16,"")) | AC16: =IF(OR($B16="",$X16=""),"",IFERROR(($X16/$K16)/('Grundeinstellungen'!$C$16*('Grundeinstellungen'!$C$6-'Grundeinstellungen'!$C$7))*3600,"")) | AD16: =IF(OR($B16="",$AC16=""),"",$AC16/'Grundeinstellungen'!$C$15*1000) | AE16: =IF(OR($B16="",$AC16=""),"",IFERROR($AC16/3600/'Grundeinstellungen'!$C$15/'Grundeinstellungen'!$J$22,"")) | AF16: =IF(OR($B16="",$AE16=""),"",IFERROR($AE16*'Grundeinstellungen'!$J$21/'Grundeinstellungen'!$C$17,"")) | AG16: =IF(OR($B16="",$AF16=""),"",IF($AF16<2300,"laminar",IF($AF16<4000,"Übergangsbereich","turbulent"))) | AH16: =IF(OR($B16="",$AF16=""),"",IF($AF16<2300,64/$AF16,0.316/$AF16^0.25)) | AI16: =IF(OR($B16="",$AH16="",$AB16=""),"",IFERROR($AH16*($AB16/'Grundeinstellungen'!$J$21)*('Grundeinstellungen'!$C$15/2)*$AE16^2,"")) | AJ16: =IF(OR($B16="",$AI16="",$AB16=""),"",IFERROR($AI16/$AB16,"")) | AK16: =IF(OR($B16="",$AI16=""),"",$AI16*(1+'Grundeinstellungen'!$C$24)+'Grundeinstellungen'!$C$25)
G17: =IF($B17="","",IFERROR($F17/$D17,"")) | N17: =IF($B17="","",IFERROR(('Grundeinstellungen'!$C$6-'Grundeinstellungen'!$C$7)/LN(('Grundeinstellungen'!$C$6-$E17)/('Grundeinstellungen'!$C$7-$E17)),"")) | O17: =IF($B17="","",IFERROR(IFERROR(INDEX('Konstanten'!$B$6:$B$10,MATCH($I17,'Konstanten'!$A$6:$A$10,1))+($I17-INDEX('Konstanten'!$A$6:$A$10,MATCH($I17,'Konstanten'!$A$6:$A$10,1)))/(INDEX('Konstanten'!$A$6:$A$10,MATCH($I17,'Konstanten'!$A$6:$A$10,1)+1)-INDEX('Konstanten'!$A$6:$A$10,MATCH($I17,'Konstanten'!$A$6:$A$10,1)))*(INDEX('Konstanten'!$B$6:$B$10,MATCH($I17,'Konstanten'!$A$6:$A$10,1)+1)-INDEX('Konstanten'!$B$6:$B$10,MATCH($I17,'Konstanten'!$A$6:$A$10,1))),INDEX('Konstanten'!$B$6:$B$10,MATCH($I17,'Konstanten'!$A$6:$A$10,1))),"")) | P17: =IF($B17="","",IFERROR(IFERROR(INDEX('Konstanten'!$C$6:$C$10,MATCH($I17,'Konstanten'!$A$6:$A$10,1))+($I17-INDEX('Konstanten'!$A$6:$A$10,MATCH($I17,'Konstanten'!$A$6:$A$10,1)))/(INDEX('Konstanten'!$A$6:$A$10,MATCH($I17,'Konstanten'!$A$6:$A$10,1)+1)-INDEX('Konstanten'!$A$6:$A$10,MATCH($I17,'Konstanten'!$A$6:$A$10,1)))*(INDEX('Konstanten'!$C$6:$C$10,MATCH($I17,'Konstanten'!$A$6:$A$10,1)+1)-INDEX('Konstanten'!$C$6:$C$10,MATCH($I17,'Konstanten'!$A$6:$A$10,1))),INDEX('Konstanten'!$C$6:$C$10,MATCH($I17,'Konstanten'!$A$6:$A$10,1))),"")) | Q17: =IF(OR($B17="",$N17="",$O17="",$P17=""),"",'Konstanten'!$C$13*$O17*$P17^(1-($J17/1000)/0.075)*'Konstanten'!$C$14^'Konstanten'!$C$16*'Konstanten'!$C$15^'Konstanten'!$C$17*$N17) | R17: =IF(OR($B17="",$Q17=""),"",$E17+$Q17/'Grundeinstellungen'!$J$6) | S17: =IF($B17="","",IFERROR(VLOOKUP($M17,'Konstanten'!$H$6:$I$13,2,FALSE),29)) | T17: =IF(OR($B17="",$Q17=""),"",$Q17*$H17) | U17: =IF(OR($B17="",$T17=""),"",$T17-$F17) | V17: =IF(OR($B17="",$T17=""),"",IFERROR($T17/$F17,"")) | W17: =IF(OR($B17="",$H17=""),"",'Grundeinstellungen'!$J$13*$H17) | X17: =IF(OR($B17="",$T17=""),"",MIN($T17,$F17)+$W17) | Y17: =IF($B17="","",IFERROR($H17/($J17/1000),"")) | Z17: =IF($B17="","",IFERROR(2*$L17*$K17,"")) | AA17: =IF(OR($B17="",$Y17="",$Z17=""),"",$Y17+$Z17) | AB17: =IF(OR($B17="",$AA17=""),"",IFERROR($AA17/$K17,"")) | AC17: =IF(OR($B17="",$X17=""),"",IFERROR(($X17/$K17)/('Grundeinstellungen'!$C$16*('Grundeinstellungen'!$C$6-'Grundeinstellungen'!$C$7))*3600,"")) | AD17: =IF(OR($B17="",$AC17=""),"",$AC17/'Grundeinstellungen'!$C$15*1000) | AE17: =IF(OR($B17="",$AC17=""),"",IFERROR($AC17/3600/'Grundeinstellungen'!$C$15/'Grundeinstellungen'!$J$22,"")) | AF17: =IF(OR($B17="",$AE17=""),"",IFERROR($AE17*'Grundeinstellungen'!$J$21/'Grundeinstellungen'!$C$17,"")) | AG17: =IF(OR($B17="",$AF17=""),"",IF($AF17<2300,"laminar",IF($AF17<4000,"Übergangsbereich","turbulent"))) | AH17: =IF(OR($B17="",$AF17=""),"",IF($AF17<2300,64/$AF17,0.316/$AF17^0.25)) | AI17: =IF(OR($B17="",$AH17="",$AB17=""),"",IFERROR($AH17*($AB17/'Grundeinstellungen'!$J$21)*('Grundeinstellungen'!$C$15/2)*$AE17^2,"")) | AJ17: =IF(OR($B17="",$AI17="",$AB17=""),"",IFERROR($AI17/$AB17,"")) | AK17: =IF(OR($B17="",$AI17=""),"",$AI17*(1+'Grundeinstellungen'!$C$24)+'Grundeinstellungen'!$C$25)
G18: =IF($B18="","",IFERROR($F18/$D18,"")) | N18: =IF($B18="","",IFERROR(('Grundeinstellungen'!$C$6-'Grundeinstellungen'!$C$7)/LN(('Grundeinstellungen'!$C$6-$E18)/('Grundeinstellungen'!$C$7-$E18)),"")) | O18: =IF($B18="","",IFERROR(IFERROR(INDEX('Konstanten'!$B$6:$B$10,MATCH($I18,'Konstanten'!$A$6:$A$10,1))+($I18-INDEX('Konstanten'!$A$6:$A$10,MATCH($I18,'Konstanten'!$A$6:$A$10,1)))/(INDEX('Konstanten'!$A$6:$A$10,MATCH($I18,'Konstanten'!$A$6:$A$10,1)+1)-INDEX('Konstanten'!$A$6:$A$10,MATCH($I18,'Konstanten'!$A$6:$A$10,1)))*(INDEX('Konstanten'!$B$6:$B$10,MATCH($I18,'Konstanten'!$A$6:$A$10,1)+1)-INDEX('Konstanten'!$B$6:$B$10,MATCH($I18,'Konstanten'!$A$6:$A$10,1))),INDEX('Konstanten'!$B$6:$B$10,MATCH($I18,'Konstanten'!$A$6:$A$10,1))),"")) | P18: =IF($B18="","",IFERROR(IFERROR(INDEX('Konstanten'!$C$6:$C$10,MATCH($I18,'Konstanten'!$A$6:$A$10,1))+($I18-INDEX('Konstanten'!$A$6:$A$10,MATCH($I18,'Konstanten'!$A$6:$A$10,1)))/(INDEX('Konstanten'!$A$6:$A$10,MATCH($I18,'Konstanten'!$A$6:$A$10,1)+1)-INDEX('Konstanten'!$A$6:$A$10,MATCH($I18,'Konstanten'!$A$6:$A$10,1)))*(INDEX('Konstanten'!$C$6:$C$10,MATCH($I18,'Konstanten'!$A$6:$A$10,1)+1)-INDEX('Konstanten'!$C$6:$C$10,MATCH($I18,'Konstanten'!$A$6:$A$10,1))),INDEX('Konstanten'!$C$6:$C$10,MATCH($I18,'Konstanten'!$A$6:$A$10,1))),"")) | Q18: =IF(OR($B18="",$N18="",$O18="",$P18=""),"",'Konstanten'!$C$13*$O18*$P18^(1-($J18/1000)/0.075)*'Konstanten'!$C$14^'Konstanten'!$C$16*'Konstanten'!$C$15^'Konstanten'!$C$17*$N18) | R18: =IF(OR($B18="",$Q18=""),"",$E18+$Q18/'Grundeinstellungen'!$J$6) | S18: =IF($B18="","",IFERROR(VLOOKUP($M18,'Konstanten'!$H$6:$I$13,2,FALSE),29)) | T18: =IF(OR($B18="",$Q18=""),"",$Q18*$H18) | U18: =IF(OR($B18="",$T18=""),"",$T18-$F18) | V18: =IF(OR($B18="",$T18=""),"",IFERROR($T18/$F18,"")) | W18: =IF(OR($B18="",$H18=""),"",'Grundeinstellungen'!$J$13*$H18) | X18: =IF(OR($B18="",$T18=""),"",MIN($T18,$F18)+$W18) | Y18: =IF($B18="","",IFERROR($H18/($J18/1000),"")) | Z18: =IF($B18="","",IFERROR(2*$L18*$K18,"")) | AA18: =IF(OR($B18="",$Y18="",$Z18=""),"",$Y18+$Z18) | AB18: =IF(OR($B18="",$AA18=""),"",IFERROR($AA18/$K18,"")) | AC18: =IF(OR($B18="",$X18=""),"",IFERROR(($X18/$K18)/('Grundeinstellungen'!$C$16*('Grundeinstellungen'!$C$6-'Grundeinstellungen'!$C$7))*3600,"")) | AD18: =IF(OR($B18="",$AC18=""),"",$AC18/'Grundeinstellungen'!$C$15*1000) | AE18: =IF(OR($B18="",$AC18=""),"",IFERROR($AC18/3600/'Grundeinstellungen'!$C$15/'Grundeinstellungen'!$J$22,"")) | AF18: =IF(OR($B18="",$AE18=""),"",IFERROR($AE18*'Grundeinstellungen'!$J$21/'Grundeinstellungen'!$C$17,"")) | AG18: =IF(OR($B18="",$AF18=""),"",IF($AF18<2300,"laminar",IF($AF18<4000,"Übergangsbereich","turbulent"))) | AH18: =IF(OR($B18="",$AF18=""),"",IF($AF18<2300,64/$AF18,0.316/$AF18^0.25)) | AI18: =IF(OR($B18="",$AH18="",$AB18=""),"",IFERROR($AH18*($AB18/'Grundeinstellungen'!$J$21)*('Grundeinstellungen'!$C$15/2)*$AE18^2,"")) | AJ18: =IF(OR($B18="",$AI18="",$AB18=""),"",IFERROR($AI18/$AB18,"")) | AK18: =IF(OR($B18="",$AI18=""),"",$AI18*(1+'Grundeinstellungen'!$C$24)+'Grundeinstellungen'!$C$25)
G19: =IF($B19="","",IFERROR($F19/$D19,"")) | N19: =IF($B19="","",IFERROR(('Grundeinstellungen'!$C$6-'Grundeinstellungen'!$C$7)/LN(('Grundeinstellungen'!$C$6-$E19)/('Grundeinstellungen'!$C$7-$E19)),"")) | O19: =IF($B19="","",IFERROR(IFERROR(INDEX('Konstanten'!$B$6:$B$10,MATCH($I19,'Konstanten'!$A$6:$A$10,1))+($I19-INDEX('Konstanten'!$A$6:$A$10,MATCH($I19,'Konstanten'!$A$6:$A$10,1)))/(INDEX('Konstanten'!$A$6:$A$10,MATCH($I19,'Konstanten'!$A$6:$A$10,1)+1)-INDEX('Konstanten'!$A$6:$A$10,MATCH($I19,'Konstanten'!$A$6:$A$10,1)))*(INDEX('Konstanten'!$B$6:$B$10,MATCH($I19,'Konstanten'!$A$6:$A$10,1)+1)-INDEX('Konstanten'!$B$6:$B$10,MATCH($I19,'Konstanten'!$A$6:$A$10,1))),INDEX('Konstanten'!$B$6:$B$10,MATCH($I19,'Konstanten'!$A$6:$A$10,1))),"")) | P19: =IF($B19="","",IFERROR(IFERROR(INDEX('Konstanten'!$C$6:$C$10,MATCH($I19,'Konstanten'!$A$6:$A$10,1))+($I19-INDEX('Konstanten'!$A$6:$A$10,MATCH($I19,'Konstanten'!$A$6:$A$10,1)))/(INDEX('Konstanten'!$A$6:$A$10,MATCH($I19,'Konstanten'!$A$6:$A$10,1)+1)-INDEX('Konstanten'!$A$6:$A$10,MATCH($I19,'Konstanten'!$A$6:$A$10,1)))*(INDEX('Konstanten'!$C$6:$C$10,MATCH($I19,'Konstanten'!$A$6:$A$10,1)+1)-INDEX('Konstanten'!$C$6:$C$10,MATCH($I19,'Konstanten'!$A$6:$A$10,1))),INDEX('Konstanten'!$C$6:$C$10,MATCH($I19,'Konstanten'!$A$6:$A$10,1))),"")) | Q19: =IF(OR($B19="",$N19="",$O19="",$P19=""),"",'Konstanten'!$C$13*$O19*$P19^(1-($J19/1000)/0.075)*'Konstanten'!$C$14^'Konstanten'!$C$16*'Konstanten'!$C$15^'Konstanten'!$C$17*$N19) | R19: =IF(OR($B19="",$Q19=""),"",$E19+$Q19/'Grundeinstellungen'!$J$6) | S19: =IF($B19="","",IFERROR(VLOOKUP($M19,'Konstanten'!$H$6:$I$13,2,FALSE),29)) | T19: =IF(OR($B19="",$Q19=""),"",$Q19*$H19) | U19: =IF(OR($B19="",$T19=""),"",$T19-$F19) | V19: =IF(OR($B19="",$T19=""),"",IFERROR($T19/$F19,"")) | W19: =IF(OR($B19="",$H19=""),"",'Grundeinstellungen'!$J$13*$H19) | X19: =IF(OR($B19="",$T19=""),"",MIN($T19,$F19)+$W19) | Y19: =IF($B19="","",IFERROR($H19/($J19/1000),"")) | Z19: =IF($B19="","",IFERROR(2*$L19*$K19,"")) | AA19: =IF(OR($B19="",$Y19="",$Z19=""),"",$Y19+$Z19) | AB19: =IF(OR($B19="",$AA19=""),"",IFERROR($AA19/$K19,"")) | AC19: =IF(OR($B19="",$X19=""),"",IFERROR(($X19/$K19)/('Grundeinstellungen'!$C$16*('Grundeinstellungen'!$C$6-'Grundeinstellungen'!$C$7))*3600,"")) | AD19: =IF(OR($B19="",$AC19=""),"",$AC19/'Grundeinstellungen'!$C$15*1000) | AE19: =IF(OR($B19="",$AC19=""),"",IFERROR($AC19/3600/'Grundeinstellungen'!$C$15/'Grundeinstellungen'!$J$22,"")) | AF19: =IF(OR($B19="",$AE19=""),"",IFERROR($AE19*'Grundeinstellungen'!$J$21/'Grundeinstellungen'!$C$17,"")) | AG19: =IF(OR($B19="",$AF19=""),"",IF($AF19<2300,"laminar",IF($AF19<4000,"Übergangsbereich","turbulent"))) | AH19: =IF(OR($B19="",$AF19=""),"",IF($AF19<2300,64/$AF19,0.316/$AF19^0.25)) | AI19: =IF(OR($B19="",$AH19="",$AB19=""),"",IFERROR($AH19*($AB19/'Grundeinstellungen'!$J$21)*('Grundeinstellungen'!$C$15/2)*$AE19^2,"")) | AJ19: =IF(OR($B19="",$AI19="",$AB19=""),"",IFERROR($AI19/$AB19,"")) | AK19: =IF(OR($B19="",$AI19=""),"",$AI19*(1+'Grundeinstellungen'!$C$24)+'Grundeinstellungen'!$C$25)
G20: =IF($B20="","",IFERROR($F20/$D20,"")) | N20: =IF($B20="","",IFERROR(('Grundeinstellungen'!$C$6-'Grundeinstellungen'!$C$7)/LN(('Grundeinstellungen'!$C$6-$E20)/('Grundeinstellungen'!$C$7-$E20)),"")) | O20: =IF($B20="","",IFERROR(IFERROR(INDEX('Konstanten'!$B$6:$B$10,MATCH($I20,'Konstanten'!$A$6:$A$10,1))+($I20-INDEX('Konstanten'!$A$6:$A$10,MATCH($I20,'Konstanten'!$A$6:$A$10,1)))/(INDEX('Konstanten'!$A$6:$A$10,MATCH($I20,'Konstanten'!$A$6:$A$10,1)+1)-INDEX('Konstanten'!$A$6:$A$10,MATCH($I20,'Konstanten'!$A$6:$A$10,1)))*(INDEX('Konstanten'!$B$6:$B$10,MATCH($I20,'Konstanten'!$A$6:$A$10,1)+1)-INDEX('Konstanten'!$B$6:$B$10,MATCH($I20,'Konstanten'!$A$6:$A$10,1))),INDEX('Konstanten'!$B$6:$B$10,MATCH($I20,'Konstanten'!$A$6:$A$10,1))),"")) | P20: =IF($B20="","",IFERROR(IFERROR(INDEX('Konstanten'!$C$6:$C$10,MATCH($I20,'Konstanten'!$A$6:$A$10,1))+($I20-INDEX('Konstanten'!$A$6:$A$10,MATCH($I20,'Konstanten'!$A$6:$A$10,1)))/(INDEX('Konstanten'!$A$6:$A$10,MATCH($I20,'Konstanten'!$A$6:$A$10,1)+1)-INDEX('Konstanten'!$A$6:$A$10,MATCH($I20,'Konstanten'!$A$6:$A$10,1)))*(INDEX('Konstanten'!$C$6:$C$10,MATCH($I20,'Konstanten'!$A$6:$A$10,1)+1)-INDEX('Konstanten'!$C$6:$C$10,MATCH($I20,'Konstanten'!$A$6:$A$10,1))),INDEX('Konstanten'!$C$6:$C$10,MATCH($I20,'Konstanten'!$A$6:$A$10,1))),"")) | Q20: =IF(OR($B20="",$N20="",$O20="",$P20=""),"",'Konstanten'!$C$13*$O20*$P20^(1-($J20/1000)/0.075)*'Konstanten'!$C$14^'Konstanten'!$C$16*'Konstanten'!$C$15^'Konstanten'!$C$17*$N20) | R20: =IF(OR($B20="",$Q20=""),"",$E20+$Q20/'Grundeinstellungen'!$J$6) | S20: =IF($B20="","",IFERROR(VLOOKUP($M20,'Konstanten'!$H$6:$I$13,2,FALSE),29)) | T20: =IF(OR($B20="",$Q20=""),"",$Q20*$H20) | U20: =IF(OR($B20="",$T20=""),"",$T20-$F20) | V20: =IF(OR($B20="",$T20=""),"",IFERROR($T20/$F20,"")) | W20: =IF(OR($B20="",$H20=""),"",'Grundeinstellungen'!$J$13*$H20) | X20: =IF(OR($B20="",$T20=""),"",MIN($T20,$F20)+$W20) | Y20: =IF($B20="","",IFERROR($H20/($J20/1000),"")) | Z20: =IF($B20="","",IFERROR(2*$L20*$K20,"")) | AA20: =IF(OR($B20="",$Y20="",$Z20=""),"",$Y20+$Z20) | AB20: =IF(OR($B20="",$AA20=""),"",IFERROR($AA20/$K20,"")) | AC20: =IF(OR($B20="",$X20=""),"",IFERROR(($X20/$K20)/('Grundeinstellungen'!$C$16*('Grundeinstellungen'!$C$6-'Grundeinstellungen'!$C$7))*3600,"")) | AD20: =IF(OR($B20="",$AC20=""),"",$AC20/'Grundeinstellungen'!$C$15*1000) | AE20: =IF(OR($B20="",$AC20=""),"",IFERROR($AC20/3600/'Grundeinstellungen'!$C$15/'Grundeinstellungen'!$J$22,"")) | AF20: =IF(OR($B20="",$AE20=""),"",IFERROR($AE20*'Grundeinstellungen'!$J$21/'Grundeinstellungen'!$C$17,"")) | AG20: =IF(OR($B20="",$AF20=""),"",IF($AF20<2300,"laminar",IF($AF20<4000,"Übergangsbereich","turbulent"))) | AH20: =IF(OR($B20="",$AF20=""),"",IF($AF20<2300,64/$AF20,0.316/$AF20^0.25)) | AI20: =IF(OR($B20="",$AH20="",$AB20=""),"",IFERROR($AH20*($AB20/'Grundeinstellungen'!$J$21)*('Grundeinstellungen'!$C$15/2)*$AE20^2,"")) | AJ20: =IF(OR($B20="",$AI20="",$AB20=""),"",IFERROR($AI20/$AB20,"")) | AK20: =IF(OR($B20="",$AI20=""),"",$AI20*(1+'Grundeinstellungen'!$C$24)+'Grundeinstellungen'!$C$25)
G21: =IF($B21="","",IFERROR($F21/$D21,"")) | N21: =IF($B21="","",IFERROR(('Grundeinstellungen'!$C$6-'Grundeinstellungen'!$C$7)/LN(('Grundeinstellungen'!$C$6-$E21)/('Grundeinstellungen'!$C$7-$E21)),"")) | O21: =IF($B21="","",IFERROR(IFERROR(INDEX('Konstanten'!$B$6:$B$10,MATCH($I21,'Konstanten'!$A$6:$A$10,1))+($I21-INDEX('Konstanten'!$A$6:$A$10,MATCH($I21,'Konstanten'!$A$6:$A$10,1)))/(INDEX('Konstanten'!$A$6:$A$10,MATCH($I21,'Konstanten'!$A$6:$A$10,1)+1)-INDEX('Konstanten'!$A$6:$A$10,MATCH($I21,'Konstanten'!$A$6:$A$10,1)))*(INDEX('Konstanten'!$B$6:$B$10,MATCH($I21,'Konstanten'!$A$6:$A$10,1)+1)-INDEX('Konstanten'!$B$6:$B$10,MATCH($I21,'Konstanten'!$A$6:$A$10,1))),INDEX('Konstanten'!$B$6:$B$10,MATCH($I21,'Konstanten'!$A$6:$A$10,1))),"")) | P21: =IF($B21="","",IFERROR(IFERROR(INDEX('Konstanten'!$C$6:$C$10,MATCH($I21,'Konstanten'!$A$6:$A$10,1))+($I21-INDEX('Konstanten'!$A$6:$A$10,MATCH($I21,'Konstanten'!$A$6:$A$10,1)))/(INDEX('Konstanten'!$A$6:$A$10,MATCH($I21,'Konstanten'!$A$6:$A$10,1)+1)-INDEX('Konstanten'!$A$6:$A$10,MATCH($I21,'Konstanten'!$A$6:$A$10,1)))*(INDEX('Konstanten'!$C$6:$C$10,MATCH($I21,'Konstanten'!$A$6:$A$10,1)+1)-INDEX('Konstanten'!$C$6:$C$10,MATCH($I21,'Konstanten'!$A$6:$A$10,1))),INDEX('Konstanten'!$C$6:$C$10,MATCH($I21,'Konstanten'!$A$6:$A$10,1))),"")) | Q21: =IF(OR($B21="",$N21="",$O21="",$P21=""),"",'Konstanten'!$C$13*$O21*$P21^(1-($J21/1000)/0.075)*'Konstanten'!$C$14^'Konstanten'!$C$16*'Konstanten'!$C$15^'Konstanten'!$C$17*$N21) | R21: =IF(OR($B21="",$Q21=""),"",$E21+$Q21/'Grundeinstellungen'!$J$6) | S21: =IF($B21="","",IFERROR(VLOOKUP($M21,'Konstanten'!$H$6:$I$13,2,FALSE),29)) | T21: =IF(OR($B21="",$Q21=""),"",$Q21*$H21) | U21: =IF(OR($B21="",$T21=""),"",$T21-$F21) | V21: =IF(OR($B21="",$T21=""),"",IFERROR($T21/$F21,"")) | W21: =IF(OR($B21="",$H21=""),"",'Grundeinstellungen'!$J$13*$H21) | X21: =IF(OR($B21="",$T21=""),"",MIN($T21,$F21)+$W21) | Y21: =IF($B21="","",IFERROR($H21/($J21/1000),"")) | Z21: =IF($B21="","",IFERROR(2*$L21*$K21,"")) | AA21: =IF(OR($B21="",$Y21="",$Z21=""),"",$Y21+$Z21) | AB21: =IF(OR($B21="",$AA21=""),"",IFERROR($AA21/$K21,"")) | AC21: =IF(OR($B21="",$X21=""),"",IFERROR(($X21/$K21)/('Grundeinstellungen'!$C$16*('Grundeinstellungen'!$C$6-'Grundeinstellungen'!$C$7))*3600,"")) | AD21: =IF(OR($B21="",$AC21=""),"",$AC21/'Grundeinstellungen'!$C$15*1000) | AE21: =IF(OR($B21="",$AC21=""),"",IFERROR($AC21/3600/'Grundeinstellungen'!$C$15/'Grundeinstellungen'!$J$22,"")) | AF21: =IF(OR($B21="",$AE21=""),"",IFERROR($AE21*'Grundeinstellungen'!$J$21/'Grundeinstellungen'!$C$17,"")) | AG21: =IF(OR($B21="",$AF21=""),"",IF($AF21<2300,"laminar",IF($AF21<4000,"Übergangsbereich","turbulent"))) | AH21: =IF(OR($B21="",$AF21=""),"",IF($AF21<2300,64/$AF21,0.316/$AF21^0.25)) | AI21: =IF(OR($B21="",$AH21="",$AB21=""),"",IFERROR($AH21*($AB21/'Grundeinstellungen'!$J$21)*('Grundeinstellungen'!$C$15/2)*$AE21^2,"")) | AJ21: =IF(OR($B21="",$AI21="",$AB21=""),"",IFERROR($AI21/$AB21,"")) | AK21: =IF(OR($B21="",$AI21=""),"",$AI21*(1+'Grundeinstellungen'!$C$24)+'Grundeinstellungen'!$C$25)
G22: =IF($B22="","",IFERROR($F22/$D22,"")) | N22: =IF($B22="","",IFERROR(('Grundeinstellungen'!$C$6-'Grundeinstellungen'!$C$7)/LN(('Grundeinstellungen'!$C$6-$E22)/('Grundeinstellungen'!$C$7-$E22)),"")) | O22: =IF($B22="","",IFERROR(IFERROR(INDEX('Konstanten'!$B$6:$B$10,MATCH($I22,'Konstanten'!$A$6:$A$10,1))+($I22-INDEX('Konstanten'!$A$6:$A$10,MATCH($I22,'Konstanten'!$A$6:$A$10,1)))/(INDEX('Konstanten'!$A$6:$A$10,MATCH($I22,'Konstanten'!$A$6:$A$10,1)+1)-INDEX('Konstanten'!$A$6:$A$10,MATCH($I22,'Konstanten'!$A$6:$A$10,1)))*(INDEX('Konstanten'!$B$6:$B$10,MATCH($I22,'Konstanten'!$A$6:$A$10,1)+1)-INDEX('Konstanten'!$B$6:$B$10,MATCH($I22,'Konstanten'!$A$6:$A$10,1))),INDEX('Konstanten'!$B$6:$B$10,MATCH($I22,'Konstanten'!$A$6:$A$10,1))),"")) | P22: =IF($B22="","",IFERROR(IFERROR(INDEX('Konstanten'!$C$6:$C$10,MATCH($I22,'Konstanten'!$A$6:$A$10,1))+($I22-INDEX('Konstanten'!$A$6:$A$10,MATCH($I22,'Konstanten'!$A$6:$A$10,1)))/(INDEX('Konstanten'!$A$6:$A$10,MATCH($I22,'Konstanten'!$A$6:$A$10,1)+1)-INDEX('Konstanten'!$A$6:$A$10,MATCH($I22,'Konstanten'!$A$6:$A$10,1)))*(INDEX('Konstanten'!$C$6:$C$10,MATCH($I22,'Konstanten'!$A$6:$A$10,1)+1)-INDEX('Konstanten'!$C$6:$C$10,MATCH($I22,'Konstanten'!$A$6:$A$10,1))),INDEX('Konstanten'!$C$6:$C$10,MATCH($I22,'Konstanten'!$A$6:$A$10,1))),"")) | Q22: =IF(OR($B22="",$N22="",$O22="",$P22=""),"",'Konstanten'!$C$13*$O22*$P22^(1-($J22/1000)/0.075)*'Konstanten'!$C$14^'Konstanten'!$C$16*'Konstanten'!$C$15^'Konstanten'!$C$17*$N22) | R22: =IF(OR($B22="",$Q22=""),"",$E22+$Q22/'Grundeinstellungen'!$J$6) | S22: =IF($B22="","",IFERROR(VLOOKUP($M22,'Konstanten'!$H$6:$I$13,2,FALSE),29)) | T22: =IF(OR($B22="",$Q22=""),"",$Q22*$H22) | U22: =IF(OR($B22="",$T22=""),"",$T22-$F22) | V22: =IF(OR($B22="",$T22=""),"",IFERROR($T22/$F22,"")) | W22: =IF(OR($B22="",$H22=""),"",'Grundeinstellungen'!$J$13*$H22) | X22: =IF(OR($B22="",$T22=""),"",MIN($T22,$F22)+$W22) | Y22: =IF($B22="","",IFERROR($H22/($J22/1000),"")) | Z22: =IF($B22="","",IFERROR(2*$L22*$K22,"")) | AA22: =IF(OR($B22="",$Y22="",$Z22=""),"",$Y22+$Z22) | AB22: =IF(OR($B22="",$AA22=""),"",IFERROR($AA22/$K22,"")) | AC22: =IF(OR($B22="",$X22=""),"",IFERROR(($X22/$K22)/('Grundeinstellungen'!$C$16*('Grundeinstellungen'!$C$6-'Grundeinstellungen'!$C$7))*3600,"")) | AD22: =IF(OR($B22="",$AC22=""),"",$AC22/'Grundeinstellungen'!$C$15*1000) | AE22: =IF(OR($B22="",$AC22=""),"",IFERROR($AC22/3600/'Grundeinstellungen'!$C$15/'Grundeinstellungen'!$J$22,"")) | AF22: =IF(OR($B22="",$AE22=""),"",IFERROR($AE22*'Grundeinstellungen'!$J$21/'Grundeinstellungen'!$C$17,"")) | AG22: =IF(OR($B22="",$AF22=""),"",IF($AF22<2300,"laminar",IF($AF22<4000,"Übergangsbereich","turbulent"))) | AH22: =IF(OR($B22="",$AF22=""),"",IF($AF22<2300,64/$AF22,0.316/$AF22^0.25)) | AI22: =IF(OR($B22="",$AH22="",$AB22=""),"",IFERROR($AH22*($AB22/'Grundeinstellungen'!$J$21)*('Grundeinstellungen'!$C$15/2)*$AE22^2,"")) | AJ22: =IF(OR($B22="",$AI22="",$AB22=""),"",IFERROR($AI22/$AB22,"")) | AK22: =IF(OR($B22="",$AI22=""),"",$AI22*(1+'Grundeinstellungen'!$C$24)+'Grundeinstellungen'!$C$25)
G23: =IF($B23="","",IFERROR($F23/$D23,"")) | N23: =IF($B23="","",IFERROR(('Grundeinstellungen'!$C$6-'Grundeinstellungen'!$C$7)/LN(('Grundeinstellungen'!$C$6-$E23)/('Grundeinstellungen'!$C$7-$E23)),"")) | O23: =IF($B23="","",IFERROR(IFERROR(INDEX('Konstanten'!$B$6:$B$10,MATCH($I23,'Konstanten'!$A$6:$A$10,1))+($I23-INDEX('Konstanten'!$A$6:$A$10,MATCH($I23,'Konstanten'!$A$6:$A$10,1)))/(INDEX('Konstanten'!$A$6:$A$10,MATCH($I23,'Konstanten'!$A$6:$A$10,1)+1)-INDEX('Konstanten'!$A$6:$A$10,MATCH($I23,'Konstanten'!$A$6:$A$10,1)))*(INDEX('Konstanten'!$B$6:$B$10,MATCH($I23,'Konstanten'!$A$6:$A$10,1)+1)-INDEX('Konstanten'!$B$6:$B$10,MATCH($I23,'Konstanten'!$A$6:$A$10,1))),INDEX('Konstanten'!$B$6:$B$10,MATCH($I23,'Konstanten'!$A$6:$A$10,1))),"")) | P23: =IF($B23="","",IFERROR(IFERROR(INDEX('Konstanten'!$C$6:$C$10,MATCH($I23,'Konstanten'!$A$6:$A$10,1))+($I23-INDEX('Konstanten'!$A$6:$A$10,MATCH($I23,'Konstanten'!$A$6:$A$10,1)))/(INDEX('Konstanten'!$A$6:$A$10,MATCH($I23,'Konstanten'!$A$6:$A$10,1)+1)-INDEX('Konstanten'!$A$6:$A$10,MATCH($I23,'Konstanten'!$A$6:$A$10,1)))*(INDEX('Konstanten'!$C$6:$C$10,MATCH($I23,'Konstanten'!$A$6:$A$10,1)+1)-INDEX('Konstanten'!$C$6:$C$10,MATCH($I23,'Konstanten'!$A$6:$A$10,1))),INDEX('Konstanten'!$C$6:$C$10,MATCH($I23,'Konstanten'!$A$6:$A$10,1))),"")) | Q23: =IF(OR($B23="",$N23="",$O23="",$P23=""),"",'Konstanten'!$C$13*$O23*$P23^(1-($J23/1000)/0.075)*'Konstanten'!$C$14^'Konstanten'!$C$16*'Konstanten'!$C$15^'Konstanten'!$C$17*$N23) | R23: =IF(OR($B23="",$Q23=""),"",$E23+$Q23/'Grundeinstellungen'!$J$6) | S23: =IF($B23="","",IFERROR(VLOOKUP($M23,'Konstanten'!$H$6:$I$13,2,FALSE),29)) | T23: =IF(OR($B23="",$Q23=""),"",$Q23*$H23) | U23: =IF(OR($B23="",$T23=""),"",$T23-$F23) | V23: =IF(OR($B23="",$T23=""),"",IFERROR($T23/$F23,"")) | W23: =IF(OR($B23="",$H23=""),"",'Grundeinstellungen'!$J$13*$H23) | X23: =IF(OR($B23="",$T23=""),"",MIN($T23,$F23)+$W23) | Y23: =IF($B23="","",IFERROR($H23/($J23/1000),"")) | Z23: =IF($B23="","",IFERROR(2*$L23*$K23,"")) | AA23: =IF(OR($B23="",$Y23="",$Z23=""),"",$Y23+$Z23) | AB23: =IF(OR($B23="",$AA23=""),"",IFERROR($AA23/$K23,"")) | AC23: =IF(OR($B23="",$X23=""),"",IFERROR(($X23/$K23)/('Grundeinstellungen'!$C$16*('Grundeinstellungen'!$C$6-'Grundeinstellungen'!$C$7))*3600,"")) | AD23: =IF(OR($B23="",$AC23=""),"",$AC23/'Grundeinstellungen'!$C$15*1000) | AE23: =IF(OR($B23="",$AC23=""),"",IFERROR($AC23/3600/'Grundeinstellungen'!$C$15/'Grundeinstellungen'!$J$22,"")) | AF23: =IF(OR($B23="",$AE23=""),"",IFERROR($AE23*'Grundeinstellungen'!$J$21/'Grundeinstellungen'!$C$17,"")) | AG23: =IF(OR($B23="",$AF23=""),"",IF($AF23<2300,"laminar",IF($AF23<4000,"Übergangsbereich","turbulent"))) | AH23: =IF(OR($B23="",$AF23=""),"",IF($AF23<2300,64/$AF23,0.316/$AF23^0.25)) | AI23: =IF(OR($B23="",$AH23="",$AB23=""),"",IFERROR($AH23*($AB23/'Grundeinstellungen'!$J$21)*('Grundeinstellungen'!$C$15/2)*$AE23^2,"")) | AJ23: =IF(OR($B23="",$AI23="",$AB23=""),"",IFERROR($AI23/$AB23,"")) | AK23: =IF(OR($B23="",$AI23=""),"",$AI23*(1+'Grundeinstellungen'!$C$24)+'Grundeinstellungen'!$C$25)
